
'use server';

import { generateProductDescription } from '@/ai/flows/generate-product-description';
import { generateProductSpecifications } from '@/ai/flows/generate-product-specifications';
import { generateProductImage } from '@/ai/flows/generate-product-image';
import { generateAdditionalProductImages } from '@/ai/flows/generate-additional-product-images';
import { solveMathProblem } from '@/ai/flows/solve-math-problem';

export async function generateProductDetails(
  productName: string,
  productImage: string,
  generateAdditionalImages: boolean,
  additionalInfo?: string
) {
  try {
    const promises = [
      generateProductDescription({ productName, productImage, additionalInfo }),
      generateProductSpecifications({ productName, productImage, additionalInfo }),
      generateProductImage({ productImage }),
    ];

    if (generateAdditionalImages) {
      promises.push(generateAdditionalProductImages({productName, productImage, additionalInfo}));
    }

    const results = await Promise.all(promises);

    const descriptionResult = results[0];
    const specificationsResult = results[1];
    const imageResult = results[2];
    const additionalImagesResult = generateAdditionalImages ? results[3] : { imageUrls: [] };


    if (!descriptionResult?.description || !specificationsResult?.specifications || !imageResult?.imageUrl) {
      throw new Error('AI failed to generate complete details.');
    }

    return {
      description: descriptionResult.description,
      specifications: specificationsResult.specifications,
      generatedImageUrl: imageResult.imageUrl,
      additionalImages: (additionalImagesResult as any).imageUrls || [],
    };
  } catch (error) {
    console.error('Error generating product details:', error);
    return {
      error:
        error instanceof Error
          ? error.message
          : 'An unknown error occurred.',
    };
  }
}

export async function solveMathProblemAction(problem: string) {
  try {
    const result = await solveMathProblem({ problem });
    if (!result) {
      throw new Error('AI failed to solve the problem.');
    }
    return result;
  } catch (error) {
    console.error('Error solving math problem:', error);
    return {
      error:
        error instanceof Error
          ? error.message
          : 'An unknown error occurred.',
    };
  }
}
